---
创建日期:
  -  2022/8/5
---
理解 hook跟回调很像 叫钩子函数
```js
// 回调函数也可叫钩子函数 ：hook   
function foo(fn){
	fn()
}
foo(()=>{}) //就是 我传给你了，回头我再来调用它， 因为我需要你的结果通过它来给我
```
#### 总结
	new 原因是函数有作用域。
	闭包 原因是 不直接操作变量。
	prototype 原因是 实例化后才能用，以及可以用this来操作。


```javascript
//结论 参数2 覆盖参数1 相同key的值 且新增不存在key:value 
const target = { a: 1, b: 2 }; 
const source = { b: 4, c: 5 }; 
const returnedTarget = Object.assign(target, source); 
console.log(target);
// expected output: Object { a: 1, b: 4, c: 5 } 

console.log(returnedTarget); 
// expected output: Object { a: 1, b: 4, c: 5 }
```

 
#### new 与不new区别？
	对象内部的方法 需要new 才能使用作用域限制。
	undefinde原因是 funcion是作用域，外部无法访问，要就得new。
```javascript
var dom = function(){ 
	var Name = "Default"; 
	this.Sex = "Boy"; 
	this.success = function(){ 
		alert("Success"); 
	}; 
};
alert(dom.Name); // Undefined 
alert(dom.Sex); // Undefined
```
	下面这种写法 会被 编译器转换为例2 的写法 ，html是对象不是函数不能被var aaa = new html 但是可以 var a = html； html.Name；
	但是访问 this.Say 就得 var s = new html.Success(); s.Say();
```javascript
 var html = { 
	 Name:'Object', 
	 Success:function(){ 
		this.Say = function(){ 
			alert("Hello,world"); 
		}; 
		alert("Obj Success"); 
	} 
 };
```
	例2
```javascript
var html = new Object(); 
html.Name = 'Object'; 
html.Success = function(){ 
	 this.Say = function(){ 
		alert("Hello,world"); 
	}; 
	 alert("Obj Success"); // 调用 先实例化 
}
var s = new html.Success(); 
s.Say();
```

	如果 Sucess 过多 写在外面 采用prototype去限制 调用的话必须先实例化才能访问
```javascript
html.Success.prototype.Show = function(){
	alert("HaHa"); 
}; //调用 就要先new 达到和写在内部一样效果 
	var s = new html.Success(); 
	s.Show();
```


#### 闭包来源
	闭包特点 return 匿名函数
	产生闭包想法 源于 变量作用域的问题 既要私有又不会每次都被自己初始化
```javascript
1、  计数器现在为 3 但是 counter 会被任何人修改的权限
var counter = 0; 
function add() { 
	return counter += 1; 
} 
add(); 
add(); 
add(); 



2、 本意是想输出 3, 但事与愿违，输出的都是 1 ! counter 每次都被自己初始化了
function add() { 
var counter = 0; 
	return counter += 1; 
} 
add(); 
add(); 
add(); 
```
	综合两种方法 产生的解决方式 闭包。
	内层函数用外层所定义的变量，从匿名函数看counter是外部函数也就是全局。
	只要匿名函数存在 则 counter就不会被销毁 且初始化一次 则add函数也就一直在。
	尤其 web缓存 用到很多
```javascript
//  这才是闭包
var add = (function ()  { 
	var counter = 0; 
	return function () {
		return counter += 1;
	} 
})(); 
add();
add(); 
add();
```

```javascript
var dom = function(){ }; 
	dom.Show = function(){ 
		alert("Show Message"); 
	};
	dom.prototype.Display = function(){ 
		alert("Property Message"); 
	}; 
	dom.Display(); //error 
	dom.Show(); 
	var d = new dom();
	d.Display();
	d.Show(); //error
```
	举例 闭包 函数定义成这样写比较省性能
```javascript
function MyObject(name, message) { 
	this.name = name.toString();
	this.message = message.toString(); 
}
MyObject.prototype.getName = function() { return this.name; }; MyObject.prototype.getMessage = function() { return this.message; };


```
#### prototype
```javascript
var dom = function(){ }; 
dom.Show = function(){ 
	alert("Show Message"); 
}; 
dom.prototype.Display = function(){ 
	alert("Property Message"); 
};
dom.Display(); //error 
dom.Show(); 
var d = new dom(); 
d.Display();
d.Show(); //error

```

	函数体内 遍历对象 的键值对 利用匿名函数闭包原理 去 给键值对赋值 得把匿名函数 独立出来
```javascript
function makeHelpCallback(help) { 
	return function() { 
	showHelp(help); 
	}; 
} 
for (var i = 0; i < helpText.length; i++) { 
	var item = helpText[i]; 
	document.getElementById(item.id).onfocus = makeHelpCallback(item.help); 
} 

//不要写成这样 由于循环在事件触发之前早已执行完毕， 变量对象item（被三个闭包所共享）已经指向了helpText的最后一项 

	document.getElementById(item.id).onfocus = function() { 
	 showHelp(item.help);
} 
或者 item 定义为 let item 就不用独立 匿名函数 
for (var i = 0; i < helpText.length; i++) { 
	let item = helpText[i]; 
	document.getElementById(item.id).onfocus = 
	makeHelpCallback(item.help); 
}
要么 用 foreach 绑定 不用for 
helpText.forEach(function(text) { 
	document.getElementById(text.id).onfocus = function() {
		showHelp(text.help); 
}
```

#### Promise
	备忘:手写的时候用上了微任务队列，目的是强制等待上一次的结果得到后才去触发判断成功还是失败，
1、采用 let [err,res] 去接收  左失败右成功
2、采用 async  可以不写 .then .catch 内部必须加 await 等待完成获取。
```javascript
async getlist() { 
	var id = '066d1b70-63cd-48c4-13ee-08d971dde511'; 
	await this.$http.get(`${clientinfo}${id}`).then(r => { 
		// 成功 
		if (r.data) {
			 this.$mHelper.toast('111');
		} else { 
			this.$mHelper.toast('验证码已发送.'); 
		} // 请求失败处理 
	}).catch(err => console.log(err));
},
```
	1、理解：	
		promise 类的出现，简化了我们去定义回调函数名，且封装好了流程逻辑， 只需要传递需要执行的回调函数逻辑就可以了。
		promise是一个异步，目的就是等待相关的代码先执行，后根据执行的结果，成功 执行成功回调，失败 执行失败回调。
		回调是因为异步无法正常接收返回结果，只能根据成功失败去调用后续逻辑。
		
	2、理解回调：（也就是实参和形参跟普通函数反过来）
		回函数是： fn函数参数有 成功回调a 、失败回调b ，两个函数，其参数是由fn 执行后的结果作为 a、b的参数则是实参。
		在外部声明a、b的时候参数则是形参。
		resolve('返回值') ->  then(res){  res-> '返回值' }
		reject('返回值')  -> catch(err){  err-> '返回值' }
	
	3、状态理解：
		 promise 把未resolve() 之前，执行中的状态叫pending 待定,
		.then()中的状态叫 fulfilled 已敲定、确定成功
		.catch()中的状态叫  rejected 已失败
		.finally() 不管 then 还是 catch 后都会执行。

	4、 all() 等待全部进入fulfilled，才会拿结果，当一个状态是rejected，则全部失败。 
	5、allSettled()  全部都进入 fulfilled 或rejected，则拿结果。 
	6、race()  只要有一个进入fulfilled 或rejected，则拿结果。 
	7、 any() 至少有一个进入fulfilled 则拿结果。
```js
all() 成功值是  [值，值, 值]
allSettled()成功值是   [{status: 'fulfilled' ,value：值}];
race() 成功值是 值。
any()成功值是 值。 //如果全是或rejected，那么err是集合，得err.errors 取值  [值，值, 值] 
```
##### 基于手写Promise时，理解Promise 方法用法
**理解不了回调看这个**
	普通函数 声明时候是形参，调用时候是实参。 
	回调函数 声明时候是实参，调用时候是形参。  
```js
function requestData(url, successCallback, failtureCallback) {
  // 模拟网络请求
  setTimeout(() => {
    if (url === "coderwhy") {
      // 成功
      let names = ["abc", "cba", "nba"]
      successCallback(names)  // names是实参
    } else { // 否则请求失败
      // 失败
      let errMessage = "请求失败, url错误"
      failtureCallback(errMessage)// errMessage也 是实参 
    }
  }, 3000);
}

// res是形参，err也是形参
requestData("kobe", (res) => {
  console.log(res)
}, (err) => {
  console.log(err)
})
 
```
**基本promise 回调写法**
，err 跟 catch 是同失败回调函数，可以替代 .catch。 因为 .then 支持两个参数 参数一 成功回调函数，参数二失败回调函数
```js
function foo() { 
  return new Promise((resolve, reject) => {
    resolve("success message")
    // reject("failture message")
  })
}

const fooPromise = foo() 
fooPromise.then((res) => {  //res 就相当于是 "success message"
  console.log(res)
}, (err) => {    // err就相当于是  "failture message"
  console.log(err)
})

 // catch方法传入的回调函数, 会在Promise执行reject函数时, 被回调

fooPromise.catch(() => {  //"failture message"

})
```
##### 多次then()
		res  一直都是 resolve() 传过来的
		then    return  值 看类型
1、如果是普通值(数值/字符串/普通对象/undefined), 那么这个普通的值被作为一个新的Promise的resolve值。 
```js
	//reutrn 一次 等于 new Promise一次
	// 如果没有 return    ===  return  undefined
promise.then(res => {
  return "aaaaaa"
}).then(res => {   // res ===  return "aaaaaa" ->resolve("aaaaaa") ->"aaaaaa"
  console.log("res:", res)
  return "bbbbbb"
})
```
2、如果是 new Promise  看这个 是resolve什么类型
```js
	//new Promise(resolve=>resolve(new Promise))
	// 等于new Promise(resolve=>resolve(111111))
promise.then(res => { 
  return new Promise((resolve, reject) => {
    setTimeout(() => {
      resolve(111111)
    }, 3000)
  })
}).then(res => { //111111
  console.log("res:", res)
})
```
3、如果是 对象，且对象实现了 resolve
```js
	//new Promise(resolve=>resolve(obj.then))
	//new Promise(resolve=>resolve(222222))
promise.then(res => {
  return {
    then: function(resolve, reject) {
      resolve(222222)
    }
  }
}).then(res => { //222222s
  console.log("res:", res)
})
```
 
##### 多次catch()
	有return时 同then()。 
1、直接传入错误，主动触发catch 
	缺点就是  少了 then 失败时候的捕获。
```js
const promise = new Promise((resolve, reject) => {
  //resolve()
  reject("rejected status")
  
  //靠异常 捕获 触发 catch
  // throw new Error("rejected status")
})
//1.当executor抛出异常时, 也是会调用错误(拒绝)捕获的回调函数的
//这种写法相当于 隐式写法不够明确。
promise.then(undefined, err => {
  console.log("err:", err)
  console.log("----------")
})
```
2、规范写法  明确了  res 是成功，   err是失败。
	
	相当于 catch 多层捕获，先捕获promise， 再捕获then  ，如果两个都成功，则不再捕获。当一个捕获触发失败则执行catch 结束。
```js
promise.then(res => { 
  // return new Promise((resolve, reject) => {
  //   reject("then rejected status")
  // })
  throw new Error("error message")
}).catch(err => {
  console.log("err:", err)
})
```
3、 catch 返回值
catch 有return 跟 then 情况一样。
```js
const promise = new Promise((resolve, reject) => {
  reject("111111")
})

promise.then(res => {
  console.log("res:", res)
}).catch(err => {
  console.log("err:", err)
  return "catch return value"
}).then(res => {
  console.log("res result:", res)
}).catch(err => {
  console.log("err result:", err)
})


```
##### all   可以把很多个  Promise 的接收放到数组里。
	等数组里的都进入 成功状态，再去执行后续操作。
	当 只要进入一个失败状态，则视为全部失败。
```js
Promise.all([p2, p1, p3, "aaaa"]).then(res => {
  console.log(res)
}).catch(err => {
  console.log("err:", err)
})
```




#### Proxy
	参数一是 被代理的对象
	参数二是  捕获器
	捕获器
		get  set has  deleteProperty  apply
	组合reflect（反射）
	大致 捕获器的 receiver 就是 target  ，receiver也叫this
#### Reflect	（是对象不是类）
	类似Object 提供了很多方法
	Reflect.getPrototypeOf()
	Reflect.defineProperty()
	get set 的参数三是this 改为自己
这API来源：
	1、还是解决缺陷，原本getPrototypeOf是应该整个新的关键词来独立，但是当初是加到Object上面了，后面迭代发现不合理于是又
	抽离出来，加到Reflect 上面。
	2、 in、delete 操作符 迭代也发现不合理。
	3、Reflect  同时也具备Proxy  的捕获器。
**执行Student函数中的内容, 但是创建出来对象是Teacher对象**
```js
function Student(name, age) {
  this.name = name
  this.age = age
}

function Teacher() {
}

// 执行Student函数中的内容, 但是创建出来对象是Teacher对象
const teacher = Reflect.construct(Student, ["why", 18], Teacher)
console.log(teacher)
console.log(teacher.__proto__ === Teacher.prototype)
```


#### 响应式
	当某个属性发生变化，相关依赖自动触发。
	把所有要执行的函数都 push 到数组 ，最后遍历去执行函数。
	用class 去封装这个 push的过程。
	用代理 去自动触发监听函数
	具体对象，拥有具体的代理 来管理。（如100个对象有100个代理来管理，不应该是由一个代理来管理那么多。）就得用Map 去管理，然后WeakMap 去管理 map  
	vue2用 defineProperty
	vue3用 Proxy

#### async-await
	es8之后用 async-await
	相当于把 生成器的  *改为 async,  yield改为 await 
```js
async function getData() {
  const res1 = await requestData("why")
  const res2 = await requestData(res1 + "aaa")
  const res3 = await requestData(res2 + "bbb")
  const res4 = await requestData(res3 + "ccc")
  console.log(res4)
}
getData()
```
基本写法
```js
//1、
async function foo1() {  } 
//2、
const foo2 = async () => { }
//3、
class Foo {
  async bar() { 
  } 
}
```
#####  与普通函数区别-返回值
	返回 一个 Promise
	不写 return  ，则是 return  undefined
	 写 return  可以是 值 、对象、 new Promise  。
```js
async function foo() { 
  console.log("foo function start~") 
  console.log("中间代码~") 
  console.log("foo function end~") 
  // 1.返回一个值
	// return   123    
  

  // 2.返回thenable 
  // return {
  //   then: function(resolve, reject) {
  //     resolve("hahahah")
  //   }
  // }
 
  // 3.返回Promise
  return new Promise((resolve, reject) => {
    setTimeout(() => {
      resolve("hehehehe")
    }, 2000)
  })
}

// 异步函数的返回值一定是一个Promise
const promise = foo()
promise.then(res => {
  console.log("promise then function exec:", res)
})
```
#####  与普通函数区别-异常
	普通函数报包异常后终止后续逻辑。
	异步函数报异常后，按Promise的reject方式去处理。
```js
async function foo() {
  console.log("foo function start~")
  console.log("中间代码~")

  // 异步函数中的异常, 会被作为异步函数返回的Promise的reject值的
  throw new Error("error message")

  console.log("foo function end~")
}


// 异步函数的返回值一定是一个Promise
foo().catch(err => {
  console.log("coderwhy err:", err)
})
console.log("后续还有代码~~~~~")
```
#####  await关键字
	成功回调
```js
function requestData() {
  return new Promise((resolve, reject) => {
    setTimeout(() => {
       resolve(222)
    }, 2000);
  })
}
 
async function foo() {
  const res1 = await requestData()
  console.log("后面的代码1", res1) //222  
  
  const res2 = await requestData()
  console.log("res2后面的代码", res2) //222 
   
  const res3 = await 123
  console.log("res3", res3) //123
   
  const res4 = await {
    then: function(resolve, reject) {
      resolve("abc")
    }
  }
  console.log("res4", res4) //abc
  
  const res5 = await new Promise((resolve) => {
    resolve("why")
  })
  console.log("res5:", res5)  //why
}
foo();
```
	失败回调
```js
function requestData() {
  return new Promise((resolve, reject) => {
    setTimeout(() => {
      reject(1111)
    }, 2000);
  })
}
//直接跳过，进入 catch
async function foo() {
  const res1 = await requestData()
  console.log("res1:", res1)   
}

foo().catch(err => {
  console.log("err:", err)  //111
})
```
##### 忘记了看 演化过程：
	目前还是给promise 结合使用 做 requers 时候，第一个的结果作为第二个的请求，这样套娃去请求。
	回调地狱： 回调里面执行回调。
举例： 执行套娃 等待上次结果作为下次请求 。
```js
// 回调地狱可以执行，但不要用。
requestData("why").then(res => {
  requestData(res + "aaa").then(res => {
    requestData(res + "bbb").then(res => {
      console.log(res)
    })
  })
})
```
2、解决回调地狱，不在嵌套里执行回调，return出去
es8开始 ，不要生成器写。
```js
requestData("why").then(res => {
  return requestData(res + "aaa")
}).then(res => {
  return requestData(res + "bbb")
}).then(res => {
  console.log(res)
})

//用 生成器 简化
function* getData() {
  const res1 = yield requestData("why")
  const res2 = yield requestData(res1 + "aaa")
  const res3 = yield requestData(res2 + "bbb")
  const res4 = yield requestData(res3 + "ccc")
  console.log(res4)
}
// 1> 手动执行生成器函数，但还是回调地狱
const generator = getData()
generator.next().value.then(res => {
  generator.next(res).value.then(res => {
    generator.next(res).value.then(res => {
      generator.next(res)
    })
  })
})

// 2>  递归写法 自动执行生成器函数，避免回调地狱写法
function execGenerator(genFn) {
  const generator = genFn()
  function exec(res) {
    const result = generator.next(res)
    if (result.done) {
      return result.value
    }
    result.value.then(res => {
      exec(res)
    })
  }
  exec()
}
execGenerator(getData)

// 3>  用库(很久不维护了)， 上面的12写不出来，官方提供了库相当于封装了
npm install co

const co = require('co')
co(getData)
```


